Workbook

Sheet Tablas
O2: PROPUESTA
A3: LEY | H3: Tabla 1 | M3: Tabla 1 | R3: Tabla 2 | W3: Tabla 3 - Gerencial
H4: Niveles 1 a 4 del Tabulador | M4: Niveles 1 a 4 del Tabulador | R4: Niveles 5 y 6 del Tabulador | W4: Nivel 7 del Tabulador
A5: Años | B5: Vacaciones | C5: Prima Vac | D5: Aguinaldo | H5: Años | I5: Vacaciones | J5: Prima Vac | K5: Aguinaldo | M5: Años | N5: Vacaciones | O5: Prima Vac | P5: Aguinaldo | R5: Años | S5: Vacaciones | T5: Prima Vac | U5: Aguinaldo | W5: Años | X5: Vacaciones | Y5: Prima Vac | Z5: Aguinaldo
A6: 1 | B6: 12 | C6: 0.25 | D6: 15 | H6: 1 | I6: 12 | J6: 0.3 | K6: 17 | M6: 1 | N6: 8 | O6: 0.3 | P6: 17 | R6: 1 | S6: 10 | T6: 0.35 | U6: 18 | W6: 1 | X6: 12 | Y6: 0.35 | Z6: 20
A7: 2 | B7: 14 | C7: 0.25 | D7: 15 | H7: 2 | I7: 14 | J7: 0.3 | K7: 17 | M7: 2 | N7: 10 | O7: 0.3 | P7: 17 | R7: 2 | S7: 12 | T7: 0.35 | U7: 18 | W7: 2 | X7: 14 | Y7: 0.35 | Z7: 20
A8: 3 | B8: 16 | C8: 0.25 | D8: 15 | H8: 3 | I8: 16 | J8: 0.3 | K8: 17 | M8: 3 | N8: 12 | O8: 0.3 | P8: 17 | R8: 3 | S8: 14 | T8: 0.35 | U8: 18 | W8: 3 | X8: 16 | Y8: 0.35 | Z8: 20
A9: 4 | B9: 18 | C9: 0.25 | D9: 15 | H9: 4 | I9: 18 | J9: 0.3 | K9: 17 | M9: 4 | N9: 14 | O9: 0.3 | P9: 17 | R9: 4 | S9: 16 | T9: 0.35 | U9: 18 | W9: 4 | X9: 18 | Y9: 0.35 | Z9: 20
A10: 5 | B10: 20 | C10: 0.25 | D10: 15 | H10: 5 | I10: 20 | J10: 0.3 | K10: 17 | M10: 5 | N10: 16 | O10: 0.3 | P10: 17 | R10: 5 | S10: 18 | T10: 0.35 | U10: 18 | W10: 5 | X10: 20 | Y10: 0.35 | Z10: 20
A11: 10 | B11: 22 | C11: 0.25 | D11: 15 | H11: 10 | I11: 22 | J11: 0.3 | K11: 17 | M11: 10 | N11: 18 | O11: 0.3 | P11: 17 | R11: 10 | S11: 20 | T11: 0.35 | U11: 18 | W11: 10 | X11: 22 | Y11: 0.35 | Z11: 20
A12: 15 | B12: 24 | C12: 0.25 | D12: 15 | H12: 15 | I12: 24 | J12: 0.3 | K12: 17 | M12: 15 | N12: 20 | O12: 0.3 | P12: 17 | R12: 15 | S12: 22 | T12: 0.35 | U12: 18 | W12: 15 | X12: 22 | Y12: 0.35 | Z12: 20
A13: 20 | B13: 26 | C13: 0.25 | D13: 15 | H13: 20 | I13: 26 | J13: 0.3 | K13: 17 | M13: 20 | N13: 22 | O13: 0.3 | P13: 17 | R13: 20 | S13: 22 | T13: 0.35 | U13: 18 | W13: 20 | X13: 22 | Y13: 0.35 | Z13: 20
A14: 25 | B14: 28 | C14: 0.25 | D14: 15 | H14: 25 | I14: 28 | J14: 0.3 | K14: 17 | M14: 25 | N14: 22 | O14: 0.3 | P14: 17 | R14: 25 | S14: 22 | T14: 0.35 | U14: 18 | W14: 25 | X14: 22 | Y14: 0.35 | Z14: 20
A15: 30 | B15: 30 | C15: 0.25 | D15: 15 | H15: 30 | I15: 30 | J15: 0.3 | K15: 17
A16: 35 | B16: 32 | C16: 0.25 | D16: 15 | H16: 35 | I16: 32 | J16: 0.3 | K16: 17
A19: Factor de Integracion | H19: Factor de Integracion | M19: Factor de Integracion | R19: Factor de Integracion | W19: Factor de Integracion
C20: 365 | J20: 365 | O20: 365 | T20: 365 | Y20: 365
A21: 1 | B21: =+(B6*C6)+D6+365 -> 383 | C21: =+B21/$C$20 -> 1.0493151 | D21: 313 | E21: =+C21*D21 -> 328.43562 | F21: 82.8 | G21: =+E21+F21 -> 411.23562 | H21: 1 | I21: =+(I6*J6)+K6+365 -> 385.6 | J21: =+I21/$C$20 -> 1.0564384 | M21: 1 | N21: =+(N6*O6)+P6+365 -> 384.4 | O21: =+N21/$O$20 -> 1.0531507 | P21: 313 | Q21: =+O21*P21+82.8 -> 412.43616 | R21: 1 | S21: =+(S6*T6)+U6+365 -> 386.5 | T21: =+S21/$T$20 -> 1.0589041 | W21: 1 | X21: =+(X6*Y6)+Z6+365 -> 389.2 | Y21: =+X21/$Y$20 -> 1.0663014
A22: 2 | B22: =+(B7*C7)+D7+365 -> 383.5 | C22: =+B22/$C$20 -> 1.0506849 | D22: 483 | E22: =+C22*D22 -> 507.48082 | F22: 83.38 | G22: =+E22+F22 -> 590.86082 | H22: 2 | I22: =+(I7*J7)+K7+365 -> 386.2 | J22: =+I22/$C$20 -> 1.0580822 | M22: 2 | N22: =+(N7*O7)+P7+365 -> 385 | O22: =+N22/$O$20 -> 1.0547945 | P22: 313 | Q22: =+O22*P22+82.8 -> 412.95068 | R22: 2 | S22: =+(S7*T7)+U7+365 -> 387.2 | T22: =+S22/$T$20 -> 1.0608219 | W22: 2 | X22: =+(X7*Y7)+Z7+365 -> 389.9 | Y22: =+X22/$Y$20 -> 1.0682192
A23: 3 | B23: =+(B8*C8)+D8+365 -> 384 | C23: =+B23/$C$20 -> 1.0520548 | H23: 3 | I23: =+(I8*J8)+K8+365 -> 386.8 | J23: =+I23/$C$20 -> 1.059726 | M23: 3 | N23: =+(N8*O8)+P8+365 -> 385.6 | O23: =+N23/$O$20 -> 1.0564384 | R23: 3 | S23: =+(S8*T8)+U8+365 -> 387.9 | T23: =+S23/$T$20 -> 1.0627397 | W23: 3 | X23: =+(X8*Y8)+Z8+365 -> 390.6 | Y23: =+X23/$Y$20 -> 1.070137
A24: 4 | B24: =+(B9*C9)+D9+365 -> 384.5 | C24: =+B24/$C$20 -> 1.0534247 | H24: 4 | I24: =+(I9*J9)+K9+365 -> 387.4 | J24: =+I24/$C$20 -> 1.0613699 | M24: 4 | N24: =+(N9*O9)+P9+365 -> 386.2 | O24: =+N24/$O$20 -> 1.0580822 | R24: 4 | S24: =+(S9*T9)+U9+365 -> 388.6 | T24: =+S24/$T$20 -> 1.0646575 | W24: 4 | X24: =+(X9*Y9)+Z9+365 -> 391.3 | Y24: =+X24/$Y$20 -> 1.0720548
A25: 5 | B25: =+(B10*C10)+D10+365 -> 385 | C25: =+B25/$C$20 -> 1.0547945 | H25: 5 | I25: =+(I10*J10)+K10+365 -> 388 | J25: =+I25/$C$20 -> 1.0630137 | M25: 5 | N25: =+(N10*O10)+P10+365 -> 386.8 | O25: =+N25/$O$20 -> 1.059726 | R25: 5 | S25: =+(S10*T10)+U10+365 -> 389.3 | T25: =+S25/$T$20 -> 1.0665753 | W25: 5 | X25: =+(X10*Y10)+Z10+365 -> 392 | Y25: =+X25/$Y$20 -> 1.0739726
A26: 10 | B26: =+(B11*C11)+D11+365 -> 385.5 | C26: =+B26/$C$20 -> 1.0561644 | H26: 10 | I26: =+(I11*J11)+K11+365 -> 388.6 | J26: =+I26/$C$20 -> 1.0646575 | M26: 10 | N26: =+(N11*O11)+P11+365 -> 387.4 | O26: =+N26/$O$20 -> 1.0613699 | R26: 10 | S26: =+(S11*T11)+U11+365 -> 390 | T26: =+S26/$T$20 -> 1.0684932 | W26: 10 | X26: =+(X11*Y11)+Z11+365 -> 392.7 | Y26: =+X26/$Y$20 -> 1.0758904
A27: 15 | B27: =+(B12*C12)+D12+365 -> 386 | C27: =+B27/$C$20 -> 1.0575342 | H27: 15 | I27: =+(I12*J12)+K12+365 -> 389.2 | J27: =+I27/$C$20 -> 1.0663014 | M27: 15 | N27: =+(N12*O12)+P12+365 -> 388 | O27: =+N27/$O$20 -> 1.0630137 | R27: 15 | S27: =+(S12*T12)+U12+365 -> 390.7 | T27: =+S27/$T$20 -> 1.070411 | W27: 15 | X27: =+(X12*Y12)+Z12+365 -> 392.7 | Y27: =+X27/$Y$20 -> 1.0758904
A28: 20 | B28: =+(B13*C13)+D13+365 -> 386.5 | C28: =+B28/$C$20 -> 1.0589041 | H28: 20 | I28: =+(I13*J13)+K13+365 -> 389.8 | J28: =+I28/$C$20 -> 1.0679452 | M28: 20 | N28: =+(N13*O13)+P13+365 -> 388.6 | O28: =+N28/$O$20 -> 1.0646575 | R28: 20 | S28: =+(S13*T13)+U13+365 -> 390.7 | T28: =+S28/$T$20 -> 1.070411 | W28: 20 | X28: =+(X13*Y13)+Z13+365 -> 392.7 | Y28: =+X28/$Y$20 -> 1.0758904
A29: 25 | B29: =+(B14*C14)+D14+365 -> 387 | C29: =+B29/$C$20 -> 1.060274 | H29: 25 | I29: =+(I14*J14)+K14+365 -> 390.4 | J29: =+I29/$C$20 -> 1.069589 | M29: 25 | N29: =+(N14*O14)+P14+365 -> 388.6 | O29: =+N29/$O$20 -> 1.0646575 | R29: 25 | S29: =+(S14*T14)+U14+365 -> 390.7 | T29: =+S29/$T$20 -> 1.070411 | W29: 25 | X29: =+(X14*Y14)+Z14+365 -> 392.7 | Y29: =+X29/$Y$20 -> 1.0758904
A30: 30 | B30: =+(B15*C15)+D15+365 -> 387.5 | C30: =+B30/$C$20 -> 1.0616438 | H30: 30 | I30: =+(I15*J15)+K15+365 -> 391 | J30: =+I30/$C$20 -> 1.0712329
A31: 35 | B31: =+(B16*C16)+D16+365 -> 388 | C31: =+B31/$C$20 -> 1.0630137 | H31: 35 | I31: =+(I16*J16)+K16+365 -> 391.6 | J31: =+I31/$C$20 -> 1.0728767

Sheet Calculo
C4: CALCULO SALARIO A EMPLEADO
C5: 2026
C8: Periodo de Nómina
C9: Días de Pago | D9: 7
C10: Días Naturales | D10: 7
C11: Domingos | D11: 0
C13: Salarios Mínimos Vigentes | P13: 1978 | Q13: 100
C14: Area Geográfica de Empresa | D14: 419.88 | E14: 374.89 | P14: 2324.24 | Q14: =+P14*Q13/P13 -> 117.50455
C15: Distrito Federal | D15: 315.04 | Q15: =+Q13-Q14 -> -17.50455
C16: UMA | D16: =+'IMSS Calculo'!E2 -> 117.31 | E16: ESTIMACION de INCREMENTO del 10%
E17: LA UMA YA ESTA ACTUALIZADA A 2025 (REAL)
C18: Datos de Empleado
C19: Salario Diario | D19: 1800
D20: =+J39 -> 1888.7671
C21: Años de Antigüedad en fecha de Baja | D21: 0
C22: Crédito Infonavit | D22: No Tiene
C23: Valor de Crédito | D23: 0
C24: Días de Bimestre | D24: 61
C26: Acumulados Mensuales para Ajuste
C27: Posición del Periodo en el Mes | D27: 1
C28: 521 - Suma de Percepciones Periódicas | D28: 0
C29: 522 - Suma de Exentos Periódicos | D29: 0
C30: 523 - ISR Antes de Subsidio | D30: 0
C31: 524 - Subsidio al Empleo Acreditado | D31: 0
B34: # | C34: Concepto | D34: Percepción | E34: Exento
B35: 1 | C35: Sueldo Ordinario | D35: =+D19*6 -> 10800
B36: 2 | C36: Séptimo Día | D36: =+D19 -> 1800 | I36: SDI
B37: 3 | C37: Horas Extras Dobles | D37: 0 | E37: =MIN(( D37+D39+D40)/2, 5*$D$16) -> 0 | I37: Salario Diario | J37: =+D19 -> 1800
B38: 4 | C38: Horas Extras Triples | D38: 0 | I38: Factor Integracion | J38: =+Tablas!C21 -> 1.0493151
B39: 5 | C39: Festivo Trabajado | D39: 0 | I39: SDI | J39: =+J37*J38 -> 1888.7671
B40: 6 | C40: Descanso Trabajado | D40: 0 | E40: 0
B41: 7 | C41: Prima Dominical | D41: 0 | E41: =+D41 -> 0 | I41: Variables | J41: 0
B42: 11 | C42: Ajuste de Faltas | D42: 0
B43: 21 | C43: Vacaciones | D43: 0 | I43: Total SDI | J43: =+J39+J41 -> 1888.7671
B44: 22 | C44: Prima Vacacional | D44: =+D43*0.35 -> 0 | E44: =MIN(D44*1, 15*$D$16) -> 0
B45: 23 | C45: Aguinaldo | D45: 0 | E45: =MIN(D45*1,30*$D$16) -> 0
B46: 24 | C46: Reparto de Utilidades (PTU) | D46: 0
B47: 31 | C47: Bono de Asistencia | D47: =+(D35+D36)*0.1 -> 1260
B48: 32 | C48: Bono de Puntualidad | D48: =+D47 -> 1260
A49: 90 | B49: 34 | C49: Otras Percepciones | D49: 0
...

Sheet Hoja1
A1: 2016 | B1: 73.04
A2: 2017 | B2: 75.49 | C2: =+B2-B1 -> 2.45
A3: 2018 | B3: 80.6 | C3: =+B3-B2 -> 5.11
A4: 2019 | B4: 84.49 | C4: =+B4-B3 -> 3.89
A5: 2020 | B5: 86.88 | C5: =+B5-B4 -> 2.39
A6: 2021 | B6: 89.62 | C6: =+B6-B5 -> 2.74
A7: 2022 | B7: 96.22 | C7: =+B7-B6 -> 6.6
A8: 2023 | B8: 103.74 | C8: =+B8-B7 -> 7.52

Sheet IMSS Calculo
E1: UMA
C2: IMSS Empleado | E2: 117.31 | G2: NUEVO TOPE SALARIAL
C3: Salario Base de Cotizacion | D3: =+Calculo!D20 -> 1888.7671 | E3: =+D3 -> 1888.7671 | G3: =+E2*25 -> 2932.75 | N3: Monto UMA | S3: Salario Minimo
C4: (X) Tasa Art. 25 | D4: 0.0025 | E4: 0.007 | N4: Enero | O4: 2021 | P4: 89.62 | S4: Enero | T4: 2020 | U4: 213.39
C5: (=) Prestaciones en Dinero | D5: =+D3*D4 -> 4.7219178 | E5: =+E3*E4 -> 13.22137 | N5: Enero | O5: 2021 A | P5: 95.28 | S5: Enero | T5: 2019 | U5: 84.49
S6: Enero | T6: 2019 | U6: 84.49
C7: Salario Base de Cotizacion | D7: =+$D$3 -> 1888.7671 | E7: =+E3 -> 1888.7671 | S7: Enero | T7: 2018 | U7: 88.36
C8: (-) 3 UMA | D8: =+E2*3 -> 351.93 | E8: =+E2*3 -> 351.93 | S8: Enero | T8: 2017 | U8: 80.04
C9: (=) Excedente | D9: =+D7-D8 -> 1536.8371 | E9: =+E7-E8 -> 1536.8371
C10: (X) Tasa Art. 106-2 | D10: 0.004 | E10: 0.011 | L10: UMA PROYECTADA | M10: 117.31
C11: (=)Cuota Diaria Art. 106-2 (E y M) | D11: =+D9*D10 -> 6.1473485 | E11: =+E9*E10 -> 16.905208
H12: Tabla de % para calculos de retiro, cesantia y vejes en edad avanzada
C13: Salario Base de Cotizacion | D13: =+$D$7 -> 1888.7671 | E13: =+E3 -> 1888.7671
C14: (X) Tasa Art 107 | D14: 0.00375 | E14: 0.0105 | H14: Limite inferior | I14: Limite superior | J14: Limite inferior salarios | K14: Limite superio salario | L14: Limite inferior salarios | M14: Limite superio salario | N14: Porcentaje aplicable
C15: (=) Pensionados y Beneficiarios Art. 107 (E y M) | D15: =+D13*D14 -> 7.0828767 | E15: =+E13*E14 -> 19.832055 | H15: 0 | I15: 1 | J15: 0 | K15: 315.04 | L15: 0 | M15: 440.87 | N15: 0.0315
H16: 1.01 | I16: 1.5 | J16: 318.1904 | K16: 175.965 | L16: 445.2787 | M16: 175.965 | N16: 0.03676
C17: Salario Base de Cotizacion | D17: =+$D$3 -> 1888.7671 | E17: =+E3 -> 1888.7671 | H17: 1.51 | I17: 2 | J17: 177.1381 | K17: 234.62 | L17: 177.1381 | M17: 234.62 | N17: 0.04851
C18: (X) Tasa Invalidez y Vida | D18: 0.00625 | E18: 0.0175 | H18: 2.01 | I18: 2.5 | J18: 235.7931 | K18: 293.275 | L18: 235.7931 | M18: 293.275 | N18: 0.05556
C19: (=) Cuota Diaria Invalidez y Vida | D19: =+D17*D18 -> 11.804795 | E19: =+E17*E18 -> 33.053425 | H19: 2.51 | I19: 3 | J19: 294.4481 | K19: 351.93 | L19: 294.4481 | M19: 351.93 | N19: 0.06026
H20: 3.01 | I20: 3.5 | J20: 353.1031 | K20: 410.585 | L20: 353.1031 | M20: 410.585 | N20: 0.06361
C21: Salario Base de Cotizacion | D21: =+$D$3 -> 1888.7671 | E21: =+E3 -> 1888.7671 | H21: 3.51 | I21: 4 | J21: 411.7581 | K21: 469.24 | L21: 411.7581 | M21: 469.24 | N21: 0.06613
C22: (X) Tasa Cesantia y Vejez | D22: 0.01125 | E22: 0.02 | H22: 4.01 | I22: En adelante | J22: 470.4131 | K22: 2932.75 | L22: 470.4131 | M22: 2932.75 | N22: 0.07513
C23: (=) Cuota Diaria Cesantia y Vejez | D23: =+D21*D22 -> 21.24863 | E23: =+E21*E22 -> 37.775342
I24: NOTA:
C25: Salario Base de Cotizacion | E25: =+E3 -> 1888.7671
C26: (X) Tasa Cesantia y Vejez | E26: =VLOOKUP(E25,$L$15:$N$22,3) -> 0.07513
C27: (=) Cuota Diaria Cesantia y Vejez | E27: =+E25*E26 -> 141.90307 | I27: El primer renglon y el 1.01 estan en VSM
I28: Del 1.5 al 4.01 son UMAS
C29: Salario Base de Cotizacion | E29: =+E3 -> 1888.7671 | I29: y el limite superior en salario es el tope de 25 UMAS
C30: (X) Guarderias y Prestaciones | E30: 0.01
C31: (=) Guarderia y Prestaciones | D31: 0 | E31: =+E29*E30 -> 18.887671
C33: Salario Minimo Gral | E33: =+E2 -> 117.31
C34: Cuota Fija | E34: 0.204
C35: (=) Cuota Fija Enfermedad y Mater Empresa | D35: 0 | E35: =+E33*E34 -> 23.93124
C37: Salario Base de Cotizacion | E37: =+E3 -> 1888.7671
C38: (X) Prima de Riesgo | E38: 0.025 | G38: 0.5
C39: (=) Monto Prima de Riesgo | D39: 0 | E39: =+E37*E38 -> 47.219178
C43: Prestaciones Dinero Art. 25 | D43: =+D5 -> 4.7219178 | E43: =+E5 -> 13.22137
C44: (=) Enfermedad Y Mat 106-2 | D44: =+D11 -> 6.1473485 | E44: =+E11 -> 16.905208
C45: (=) Pensionados y Benefic Art. 107 | D45: =+D15 -> 7.0828767 | E45: =+E15 -> 19.832055
...

Sheet 2021
A2: EMPRESA | B2: Prima RT 2021
B3: 0.52779
B4: 0.68559 | C4: 0.69559
B5: 0.5
B6: 0.5
B7: 0.89384
B8: 0.5
B9: 2.50364
B10: 0.5
B11: 0.5
B12: 0.56122
B13: 0.9802 | C13: 0.9902
B14: 0.78573
B15: 0.62371 | C15: 0.63371
B16: 4.65325
B17: 0.52795
B18: 2.07534
B20: 4.65325

Sheet Simulacion
B3: SIMULACION SALARIO
B5: Percepcion:
C6: Sueldo Ordinario | D6: =+Calculo!D35 -> 10800
C7: Septimo Dia | D7: =+Calculo!D36 -> 1800
C8: Bono Puntualidad | D8: =+Calculo!D47 -> 1260
C9: Bono Asistencia | D9: =+Calculo!D48 -> 1260
C10: Total Percepcion | D10: =SUM(D6:D9) -> 15120 | E10: 5760
B12: Deduccion:
C13: IMSS Trabajador | D13: =+Calculo!D61 -> 357.03897
C14: ISPT Trabajador | D14: =+Calculo!D58 -> 3093.65
C15: Ajuste Moneda | D15: 0
C16: Total Deducciones | D16: =SUM(D13:D15) -> 3450.689
C19: Neto a Pagar | D19: =+D10-D16 -> 11669.311
C20: Sodexo | D20: =+Calculo!D64 -> 200
C21: Neto + Sodexo | D21: =+D19+D20 -> 11869.311 | E21: 21465.25 | F21: =+D21+E21 -> 33334.561
B22: Impuesto Patronal
C23: IMSS Empresa | D23: =+Calculo!I79 -> 1211.351
C24: Infonavit | D24: =+Calculo!I81 -> 661.06849
C25: RCV | D25: =+Calculo!I83 -> 1257.7489
C26: Impuesto Estatal | D26: =+Calculo!I85 -> 692.496
C27: Total Patronales | D27: =SUM(D23:D26) -> 3822.6644
C29: Costo nomina | D29: =+D10+D27+D20 -> 19142.664
C31: provision de FQ | D31: =+(((12*D7)*0.25)+(12*D7)+(15*D7))/52 -> 1038.4615
A33: Comedor | D33: 0
B35: Precio | C35: Meses
A36: Glucometro | B36: 8.23 | C36: 1 | D36: =+B36*1.15 -> 9.4645
A37: Cubrebocas | B37: 4.21 | C37: 1 | D37: =+B37*1.15 -> 4.8415
A38: Total | D38: =SUM(D36:D37) -> 14.306
A40: Jornada | D40: 48
A41: Utilidad | D41: 500
A44: OVH | D44: 12.8
A45: Variables | D45: 0.93
A46: Utilidad | D46: =+D41/D40 -> 10.416667
A47: Costo Hra | D47: =+D29/D40 -> 398.80551
A48: Costos EPP | D48: =+D38/D40 -> 0.29804167
A49: Provision de FQ | D49: =+D31/D40 -> 21.634615
A50: Comedor | D50: =+D33/D40 -> 0
A51: Costo Hra Cliente | D51: =SUM(D44:D50) -> 444.88483

Sheet Sheet5
B3: SIMULACION SALARIO
B5: Percepcion:
C6: Sueldo Ordinario | D6: 13518.66
C7: Septimo Dia | D7: 2253.11
C8: Bono Puntualidad | D8: 1577.177
C9: Bono Asistencia | D9: 1577.177
C10: Total Percepcion | D10: 18926.124
B12: Deduccion:
C13: IMSS Trabajador | D13: 450.53602
C14: ISPT Trabajador | D14: 4403.79
C15: Ajuste Moneda | D15: 0
C16: Total Deducciones | D16: 4854.326
C19: Neto a Pagar | D19: 14071.798
C20: Sodexo | D20: 200
C21: Neto + Sodexo | D21: 14271.798
B22: Impuesto Patronal
C23: IMSS Empresa | D23: 1464.6908
C24: Infonavit | D24: 827.4778
C25: RCV | D25: 1032.8578
C26: Impuesto Estatal | D26: 866.81648
C27: Total Patronales | D27: 4191.8429
C29: Costo nomina | D29: 23317.967

Sheet Sheet1
C3: SIMULACION SALARIO
C5: Percepcion: | G5: 30 | I5: 45 | K5: 60 | M5: 90
D6: Sueldo Ordinario | E6: 18719.4 | G6: 18719.4 | I6: 18719.4 | K6: 18719.4 | M6: 18719.4
D7: Septimo Dia | E7: 3119.9 | G7: 3119.9 | I7: 3119.9 | K7: 3119.9 | M7: 3119.9
D8: T. Extra | E8: 0 | G8: 0 | I8: 0 | K8: 0 | M8: 0
D9: Bono Puntualidad | E9: 2183.93 | G9: 2183.93 | I9: 2183.93 | K9: 2183.93 | M9: 2183.93
D10: Bono Asistencia | E10: 2183.93 | G10: 2183.93 | I10: 2183.93 | K10: 2183.93 | M10: 2183.93
D11: Aguinaldo | E11: 23960.832 | G11: 23960.832 | I11: 23960.832 | K11: 23960.832 | M11: 23960.832
D12: Vacaciones | E12: 107511.75 | G12: 107511.75 | I12: 107511.75 | K12: 107511.75 | M12: 107511.75
D13: Prima | E13: 37629.114 | G13: 37629.114 | I13: 37629.114 | K13: 37629.114 | M13: 37629.114
D14: Compensacion | E14: 0 | G14: 93597 | I14: 140395.5 | K14: 187194 | M14: 280791
D15: Total Percepcion | E15: =SUM(E6:E14) -> 195308.86 | G15: =SUM(G6:G14) -> 288905.86 | I15: =SUM(I6:I14) -> 335704.36 | K15: =SUM(K6:K14) -> 382502.86 | M15: =SUM(M6:M14) -> 476099.86
C17: Deduccion:
D18: IMSS Trabajador | E18: 642.78849 | G18: 3240.1052 | I18: 4538.7636 | K18: 5837.422 | M18: 8434.7387
D19: ISPT Trabajador | E19: 113552.73 | G19: 146311.68 | I19: 162691.15 | K19: 179070.63 | M19: 211829.58
D20: Ajuste Moneda
D21: Total Deducciones | E21: =SUM(E18:E20) -> 114195.52 | G21: =SUM(G18:G20) -> 149551.79 | I21: =SUM(I18:I20) -> 167229.91 | K21: =SUM(K18:K20) -> 184908.05 | M21: =SUM(M18:M20) -> 220264.32
D24: Neto a Pagar | E24: =+E15-E21 -> 81113.341 | G24: =+G15-G21 -> 139354.07 | I24: =+I15-I21 -> 168474.45 | K24: =+K15-K21 -> 197594.81 | M24: =+M15-M21 -> 255835.54
D25: Sodexo | E25: 200 | G25: 200 | I25: 200 | K25: 200 | M25: 200
D26: Neto + Sodexo | E26: =+E24+E25 -> 81313.341 | G26: =+G24+G25 -> 139554.07 | I26: =+I24+I25 -> 168674.45 | K26: =+K24+K25 -> 197794.81 | M26: =+M24+M25 -> 256035.54
C27: Impuesto Patronal
D28: IMSS Empresa | E28: 1545.9187 | G28: 7255.3357 | I28: 10110.044 | K28: 12964.753 | M28: 18674.17
D29: Infonavit | E29: 841.925 | G29: 841.925 | I29: 841.925 | K29: 841.925 | M29: 841.925
D30: RCV | E30: 1207.9227 | G30: 6028.1682 | I30: 8438.291 | K30: 10848.414 | M30: 15668.659
D31: Impuesto Estatal | E31: 5859.2658 | G31: 8667.1758 | I31: 10071.131 | K31: 11475.086 | M31: 14282.996
D32: Total Patronales | E32: =SUM(E28:E31) -> 9455.0322 | G32: =SUM(G28:G31) -> 22792.605 | I32: =SUM(I28:I31) -> 29461.391 | K32: =SUM(K28:K31) -> 36130.177 | M32: =SUM(M28:M31) -> 49467.75
E34: =+E15+E25+E32 -> 204963.89 | G34: =+G15+G25+G32 -> 311898.46 | I34: =+I15+I25+I32 -> 365365.75 | K34: =+K15+K25+K32 -> 418833.04 | M34: =+M15+M25+M32 -> 525767.61
M38: =+E15+E25+EFQ32 -> 195508.86

Sheet Sheet2
G3: SIN SODEX
A4: Percepcion:
B5: Sueldo Ordinario | C5: 5136.42 | E5: 4179.54 | G5: 5331 | I5: 4368
B6: Septimo Dia | C6: 856.07 | E6: 696.59 | G6: 888.5 | I6: 728
B7: T. Extra | C7: 0 | E7: 0 | G7: 0 | I7: $ -
B8: Bono Puntualidad | C8: 599.249 | E8: 487.613 | G8: 621.95 | I8: 509.6
B9: Bono Asistencia | C9: 599.249 | E9: 487.613 | G9: 621.95 | I9: 509.6
B10: Total Percepcion | C10: 7190.988 | E10: 5851.356 | G10: 7463.4 | I10: 6115.2
A12: Deduccion:
B13: IMSS Trabajador | C13: 165.72641 | E13: 133.347 | G13: 172.31071 | I13: 139.72
B14: ISPT Trabajador | C14: 1225.24 | E14: 918 | G14: 1289.31 | I14: 974.36
B15: Ajuste Moneda
B16: Total Deducciones | C16: 1390.9664 | E16: 1051.347 | G16: 1461.6207 | I16: 1114.08
B19: Neto a Pagar | C19: 5800.0216 | E19: 4800.009 | G19: 6001.7793 | I19: 5001.12
B20: Sodexo | C20: 200 | E20: 200 | G20: 0 | I20: -
B21: Neto + Sodexo | C21: 6000.0216 | E21: 5000.009 | G21: 6001.7793 | I21: 5001.12
A22: Impuesto Patronal
B23: IMSS Empresa | C23: 497.24173 | E23: 426.06537 | G23: 511.71532 | I23: 440.08
B24: Infonavit | C24: 313.16917 | E24: 254.82789 | G24: 325.03277 | I24: 266.32
B25: RCV | C25: 322.56424 | E25: 262.47273 | G25: 334.78376 | I25: 274.31
B26: Impuesto Estatal | C26: 215.72964 | E26: 175.54068 | G26: 223.902 | I26: 183.46
B27: Total Patronales | C27: 1348.7048 | E27: 1118.9067 | G27: 1395.4339 | I27: 1164.17
C29: 8539.6928 | E29: 6970.2627 | G29: 8858.8339 | I29: 7279.37
C31: =+C21*4 -> 24000.086 | E31: =+E21*4 -> 20000.036 | G31: =+G21*4 -> 24007.117 | I31: =+I21*4 -> 20004.48

Sheet Sheet3
A1: Nota
A2: 0.0658875 | B2: Hyundai
A3: 2.5 | B3: Todas las demas

Sheet 33 Hilos 
B3: SIMULACION SALARIO | G3: SIMULACION SALARIO
B5: Percepcion: | G5: Percepcion:
C6: Sueldo Ordinario | D6: 13518.66 | H6: Sueldo Ordinario | I6: 13518.66
C7: Septimo Dia | D7: 2253.11 | H7: Septimo Dia | I7: 2253.11
C8: Bono Puntualidad | D8: 1577.177 | H8: Bono Puntualidad | I8: 1577.177
C9: Bono Asistencia | D9: 1577.177 | H9: Bono Asistencia | I9: 1577.177
C10: Total Percepcion | D10: 18926.124 | H10: Total Percepcion | I10: 18926.124
B12: Deduccion: | G12: Deduccion:
C13: IMSS Trabajador | D13: 450.53602 | H13: IMSS Trabajador | I13: 450.53602
C14: ISPT Trabajador | D14: 4403.79 | H14: ISPT Trabajador | I14: 4403.79
C15: Ajuste Moneda | D15: 0 | H15: Ajuste Moneda | I15: 0
C16: Total Deducciones | D16: 4854.326 | H16: Total Deducciones | I16: 4854.326
C19: Neto a Pagar | D19: 14071.798 | H19: Neto a Pagar | I19: 14071.798
C20: Sodexo | D20: 200 | H20: Sodexo | I20: 200
C21: Neto + Sodexo | D21: 14271.798 | H21: Neto + Sodexo | I21: 14271.798
B22: Impuesto Patronal | G22: Impuesto Patronal
C23: IMSS Empresa | D23: 1464.6908 | H23: IMSS Empresa | I23: 1464.6908
C24: Infonavit | D24: 827.4778 | H24: Infonavit | I24: 827.4778
C25: RCV | D25: 1032.8578 | H25: RCV | I25: 1032.8578
C26: Impuesto Estatal | D26: 866.81648 | H26: Impuesto Estatal | I26: 866.81648
C27: Total Patronales | D27: 4191.8429 | H27: Total Patronales | I27: 4191.8429
C29: Costo nomina | D29: 23317.967 | H29: Costo nomina | I29: 23317.967
